Workbook

Sheet README
B1: COMSTAR Hospital ROI Model
B2: First-glance estimate. Version 1.0, August 2026.
B4: What this is
B5: A capacity and return model for deploying an addressable edge-intelligence layer in a hospital,
B6: covering the six outcomes described in 'COMSTAR: The Addressable Hospital' (White Paper v1.0).
B7: It is a first-glance estimate built on public aggregate data and stated assumptions. It is not a
B8: business case. Every figure should be replaced with the target facility's own measurements.
B10: How to use it
B11: 1. Open 'Assumptions' and change any BLUE cell. Every other sheet recalculates.
B12: 2. YELLOW cells are the levers that move the answer most. Test those first.
B13: 3. 'Outcomes' shows value and FTE effect per use case.
B14: 4. 'Investment' shows capital and operating cost, full deployment and phased entry.
... B38: Prepared alongside 'COMSTAR: The Addressable Hospital', White Paper v1.0. CC BY 4.0.

Sheet Assumptions
B1: Assumptions
B2: Edit BLUE cells only. Yellow fill marks the levers that move the answer most.
B4: FACILITY
B5: Staffed beds | C5: 400 | D5: beds | E5: Reference facility. Average US bed sits in a ~400-bed hospital.
B6: Average occupancy | C6: 0.7 | E6: Drives census and the value of recovered bed-time.
B7: Average length of stay | C7: 4.7 | D7: days
B8: Annual ED visits | C8: 70000 | D8: visits | E8: ~175 per bed per year, national average.
B9: Operating rooms | C9: 18 | D9: rooms | E9: ~1 per 22 beds.
B10: First cases per OR per year | C10: 250 | D10: cases
B11: Contribution margin per admission | C11: 1500 | D11: $ | E11: Ranges <$1,000 safety-net to >$5,000 commercial.
B13: WORKFORCE
B14: RN FTEs | C14: 750 | D14: FTE | E14: From ~1,000 headcount across all shifts.
B15: RN fully loaded cost | C15: 125000 | D15: $/yr | E15: Salary, benefits, tax. Excludes agency premium.
B16: Productive hours per FTE per year | C16: 2080 | D16: hrs
B17: Employed physician FTEs | C17: 90 | D17: FTE | E17: Excludes privileged-only medical staff.
B18: Physician fully loaded cost | C18: 400000 | D18: $/yr | E18: Blended across specialties.
B19: Physician working days per year | C19: 220 | D19: days
B20: EVS FTEs | C20: 60 | D20: FTE
B21: EVS fully loaded cost | C21: 45000 | D21: $/yr
B22: Sitter hourly fully loaded cost | C22: 22 | D22: $/hr
B24: OUTCOME 1: ASSET LOCATION AND READINESS
B25: Search time per nurse per 12h shift | C25: 15 | D25: min | E25: Literature range 10-30 min. Conservative end used.
B26: Share of search time recoverable | C26: 0.6 | E26: Not all search is eliminable.
B27: Annual equipment rental avoided | C27: 180000 | D27: $ | E27: Hospitals rent what they own but cannot find.
B28: Annual deferred capital purchase | C28: 250000 | D28: $ | E28: Utilisation gain defers fleet expansion.
B30: OUTCOME 2: ROOM READINESS AND TURNOVER
B31: Bed turnaround time reduction | C31: 20 | D31: min | E31: From actual-clean to known-clean.
B32: EVS reporting time saved per FTE per shift | C32: 8 | D32: min
B33: LWBS rate reduction | C33: 0.005 | E33: Left-without-being-seen, half a point.
B34: Margin per ED visit converted | C34: 400 | D34: $
B36: OUTCOME 3: SCHEDULE AND CONFLICT DETECTION
B37: First-case on-time start, baseline | C37: 0.65 | E37: Typical baseline.
B38: First-case on-time start, target | C38: 0.8
B39: Average delay avoided per case | C39: 20 | D39: min
B40: Fully loaded OR cost per minute | C40: 40 | D40: $/min | E40: Staff, room, opportunity.
B41: Same-day cancellations avoided | C41: 50 | D41: cases
B42: Contribution margin per surgical case | C42: 4000 | D42: $
B44: OUTCOME 4: AMBIENT CLINICAL DOCUMENTATION
B45: Documentation time saved per MD per day | C45: 45 | D45: min | E45: Vendor claims 60-90. Discounted.
B46: Share realised as usable capacity | C46: 0.4 | E46: Rest returns as reduced burnout, not throughput.
...

Sheet Outcomes
B1: Value by outcome
B2: All figures annual, at full realisation, before the soft-dollar discount.
B4: Outcome / component | C4: Annual value | D4: FTE-equivalent | E4: Type | F4: Basis
B5: 1. ASSET LOCATION AND READINESS
B6: Nursing search time recovered | C6: =Assumptions!C14*Assumptions!C16*(Assumptions!C25/(12*60))*Assumptions!C26*(Assumptions!C15/Assumptions!C16) -> 1171875 | D6: =Assumptions!C14*(Assumptions!C25/(12*60))*Assumptions!C26 -> 9.375 | E6: Augment | F6: 15 min/shift x 60% recoverable across 750 RN FTEs
B7: Equipment rental avoided | C7: =Assumptions!C27 -> 180000 | E7: Cash | F7: Renting owned-but-unfindable equipment
B8: Deferred capital purchase | C8: =Assumptions!C28 -> 250000 | E8: Capital | F8: Utilisation gain defers fleet expansion
B9: Subtotal, Outcome 1 | C9: =SUM(C6:C8) -> 1601875 | D9: =D6 -> 9.375
B11: 2. ROOM READINESS AND TURNOVER
B12: Bed-days recovered from faster turnaround | C12: =((Assumptions!C5*365*Assumptions!C6)/Assumptions!C7)*(Assumptions!C31/(24*60))*Assumptions!C11/Assumptions!C7 -> 96385.997 | F12: Recovered bed-days x margin, only valuable if capacity-constrained
B13: ED left-without-being-seen reduction | C13: =Assumptions!C8*Assumptions!C33*Assumptions!C34 -> 140000
B14: EVS reporting time recovered | C14: =Assumptions!C20*Assumptions!C16*(Assumptions!C32/(8*60))*(Assumptions!C21/Assumptions!C16) -> 45000 | D14: =Assumptions!C20*(Assumptions!C32/(8*60)) -> 1 | E14: Augment
B15: Subtotal, Outcome 2 | C15: =SUM(C12:C14) -> 281386 | D15: =D14 -> 1
B17: 3. SCHEDULE AND CONFLICT DETECTION
B18: OR minutes recovered, on-time starts | C18: =Assumptions!C9*Assumptions!C10*(Assumptions!C38-Assumptions!C37)*Assumptions!C39*Assumptions!C40 -> 540000 | F18: 4,500 first cases x 15pt improvement x 20 min x $40/min
B19: Same-day cancellations avoided | C19: =Assumptions!C41*Assumptions!C42 -> 200000
B20: Coordination time recovered | C20: =1.5*Assumptions!C15 -> 187500 | D20: 1.5 | E20: Augment | F20: Charge nurse and coordinator reconciliation effort
B21: Subtotal, Outcome 3 | C21: =SUM(C18:C20) -> 927500 | D21: =D20 -> 1.5
B23: 4. AMBIENT CLINICAL DOCUMENTATION
B24: Physician time recovered | C24: =Assumptions!C17*Assumptions!C19*(Assumptions!C45/60)*Assumptions!C46*(Assumptions!C18/(Assumptions!C19*8)) -> 1350000 | D24: =Assumptions!C17*(Assumptions!C45/(8*60)) -> 8.4375 | E24: Augment
B25: Physician retention | C25: =Assumptions!C47*Assumptions!C48 -> 250000
B26: Cloud subscription avoided | C26: =Assumptions!C17*Assumptions!C49*12 -> 324000 | E26: Cash | F26: The true alternative is buying a cloud product, not doing nothing
B27: Subtotal, Outcome 4 | C27: =SUM(C24:C26) -> 1924000 | D27: =D24 -> 8.4375
B29: 5. PATIENT INTERACTION
B30: Call-light response time deflected | C30: =(Assumptions!C5*Assumptions!C6)*Assumptions!C52*365*(Assumptions!C53/60)*Assumptions!C54*Assumptions!C55*(Assumptions!C15/Assumptions!C16) -> 409455.13 | D30: =((Assumptions!C5*Assumptions!C6)*Assumptions!C52*365*(Assumptions!C53/60)*Assumptions!C54*Assumptions!C55)/Assumptions!C16 -> 3.275641 | E30: Augment | F30: Informational call lights only, clinical requests still escalate
B31: Subtotal, Outcome 5 | C31: =C30 -> 409455.13 | D31: =D30 -> 3.275641
B33: 6. SAFETY OBSERVATION
B34: Sitter hours eliminated, net of monitor techs | C34: =Assumptions!C58*24*365*Assumptions!C59*Assumptions!C22-Assumptions!C60*Assumptions!C61 -> 1280400 | D34: =(Assumptions!C58*24*365*Assumptions!C59)/Assumptions!C16-Assumptions!C60 -> 28.586538 | E34: REPLACE | F34: The only genuine headcount reduction, and the hardest to approve
B35: Injurious falls prevented | C35: =Assumptions!C62*Assumptions!C63 -> 400000 | F35: Non-reimbursable under CMS hospital-acquired condition rules
B36: Subtotal, Outcome 6 | C36: =SUM(C34:C35) -> 1680400 | D36: =D34 -> 28.586538
B38: TOTAL, ALL SIX OUTCOMES | C38: =C9+C15+C21+C27+C31+C36 -> 6824616.1 | D38: =D9+D15+D21+D27+D31+D36 -> 52.174679
B39: of which augment (soft dollars) | C39: =C38-C36 -> 5144216.1
B40: of which actual headcount reduction | C40: =C36 -> 1680400 | D40: =D36 -> 28.586538
B41: Phase 0+1 only (outcomes 1-3, no PHI, no cameras) | C41: =C9+C15+C21 -> 2810761 | D41: =D9+D15+D21 -> 11.875 | F41: No regulatory approval, no consent framework, no device pathway
B43: After soft-dollar discount
B44: Total, discounted | C44: =C36+(C38-C36)*(1-Assumptions!C85) -> 6824616.1 | F44: Finance will apply 30-50% to augment outcomes. Set it on Assumptions.
B45: Phase 0+1, discounted | C45: =C41*(1-Assumptions!C85) -> 2810761

Sheet Investment
B1: Investment and operating cost
B3: Item | C3: Full deployment | D3: Phase 0+1 | E3: Note
B4: CAPITAL
B5: Terminals | C5: =Assumptions!C66*Assumptions!C67 -> 420000 | D5: =Assumptions!C72*Assumptions!C67 -> 70000 | E5: Device, mount, panel, install labour
B6: Compute and servers | C6: =Assumptions!C68 -> 325000 | D6: =Assumptions!C73 -> 120000 | E6: Accelerators plus hosts
B7: UWB / RTLS extension | C7: =Assumptions!C69 -> 400000 | D7: =Assumptions!C74 -> 150000 | E7: Anchors, tags, integration
B8: Integration and services | C8: =Assumptions!C70 -> 700000 | D8: =Assumptions!C75 -> 250000 | E8: Tool layer to hospital systems
B9: Private 5G | C9: =Assumptions!C71 -> 800000 | D9: =0 -> 0 | E9: Deferred in phase 0+1; often shared across a system
B10: Total capital | C10: =SUM(C5:C9) -> 2645000 | D10: =SUM(D5:D9) -> 590000
B12: ANNUAL OPERATING
B13: Support and maintenance | C13: =Assumptions!C78*Investment!C10 -> 396750 | D13: =Assumptions!C78*Investment!D10 -> 88500 | E13: Percentage of capital
B14: Internal platform staff | C14: =Assumptions!C79*Assumptions!C80 -> 280000 | D14: =Assumptions!C79*Assumptions!C80*0.5 -> 140000 | E14: Half an allocation in phase 0+1
B15: Power | C15: =Assumptions!C81 -> 25000 | D15: =Assumptions!C81*0.3 -> 7500
B16: Models and licences | C16: =Assumptions!C82 -> 100000 | D16: =Assumptions!C82*0.5 -> 50000
B17: Total annual operating | C17: =SUM(C13:C16) -> 801750 | D17: =SUM(D13:D16) -> 286000

Sheet Returns
B1: Returns
B2: Benefits ramp per the realisation assumptions. Capital in year 0.
B4: FULL DEPLOYMENT, ALL SIX OUTCOMES
C5: Year 0 | D5: Year 1 | E5: Year 2 | F5: Year 3 | G5: Year 4 | H5: Year 5
B6: Realisation | C6: 0 | D6: =Assumptions!C86 -> 0.3 | E6: =Assumptions!C87 -> 0.8 | F6: =Assumptions!C88 -> 1 | G6: =Assumptions!C88 -> 1 | H6: =Assumptions!C88 -> 1
B7: Benefit | C7: 0 | D7: =Outcomes!C44*D6 -> 2047384.8 | E7: =Outcomes!C44*E6 -> 5459692.9 | F7: =Outcomes!C44*F6 -> 6824616.1 | G7: =Outcomes!C44*G6 -> 6824616.1 | H7: =Outcomes!C44*H6 -> 6824616.1
B8: Operating cost | C8: 0 | D8: =-Investment!C17 -> -801750 | E8: =-Investment!C17 -> -801750 | F8: =-Investment!C17 -> -801750 | G8: =-Investment!C17 -> -801750 | H8: =-Investment!C17 -> -801750
B9: Capital | C9: =-Investment!C10 -> -2645000 | D9: 0 | E9: 0 | F9: 0 | G9: 0 | H9: 0
B10: Net cash flow | C10: =C7+C8+C9 -> -2645000 | D10: =D7+D8+D9 -> 1245634.8 | E10: =E7+E8+E9 -> 4657942.9 | F10: =F7+F8+F9 -> 6022866.1 | G10: =G7+G8+G9 -> 6022866.1 | H10: =H7+H8+H9 -> 6022866.1
B11: Cumulative | C11: =C10 -> -2645000 | D11: =C11+D10 -> -1399365.2 | E11: =D11+E10 -> 3258577.7 | F11: =E11+F10 -> 9281443.9 | G11: =F11+G10 -> 15304310 | H11: =G11+H10 -> 21327176
B13: NPV (5 yr) | C13: =C10+NPV(Assumptions!C89,D10:H10) -> 15808994
B14: IRR | C14: =IFERROR(IRR(C10:H10),"n/a") -> 1.1366387
B15: Payback crossing (helper) | D15: =IF(AND(C11<0,D11>=0),12*0+12*(-C11/D10),9999) -> 9999 | E15: =IF(AND(D11<0,E11>=0),12*1+12*(-D11/E10),9999) -> 15.605107 | F15: =IF(AND(E11<0,F11>=0),12*2+12*(-E11/F10),9999) -> 9999 | G15: =IF(AND(F11<0,G11>=0),12*3+12*(-F11/G10),9999) -> 9999 | H15: =IF(AND(G11<0,H11>=0),12*4+12*(-G11/H10),9999) -> 9999
B16: Payback (months) | C16: =IF(MIN(D15:H15)>=9999,"beyond 5 yrs",MIN(D15:H15)) -> 15.605107
B17: 5-year cumulative return on capital | C17: =IFERROR(H11/Investment!C10,0) -> 8.0632046
B20: PHASE 0+1 ONLY, OUTCOMES 1-3 (no PHI, no cameras, no biometrics)
C21: Year 0 | D21: Year 1 | E21: Year 2 | F21: Year 3 | G21: Year 4 | H21: Year 5
B22: Realisation | C22: 0 | D22: =Assumptions!C86 -> 0.3 | E22: =Assumptions!C87 -> 0.8 | F22: =Assumptions!C88 -> 1 | G22: =Assumptions!C88 -> 1 | H22: =Assumptions!C88 -> 1
B23: Benefit | C23: 0 | D23: =Outcomes!C45*D22 -> 843228.3 | E23: =Outcomes!C45*E22 -> 2248608.8 | F23: =Outcomes!C45*F22 -> 2810761 | G23: =Outcomes!C45*G22 -> 2810761 | H23: =Outcomes!C45*H22 -> 2810761
B24: Operating cost | C24: 0 | D24: =-Investment!D17 -> -286000 | E24: =-Investment!D17 -> -286000 | F24: =-Investment!D17 -> -286000 | G24: =-Investment!D17 -> -286000 | H24: =-Investment!D17 -> -286000
B25: Capital | C25: =-Investment!D10 -> -590000 | D25: 0 | E25: 0 | F25: 0 | G25: 0 | H25: 0
B26: Net cash flow | C26: =C23+C24+C25 -> -590000 | D26: =D23+D24+D25 -> 557228.3 | E26: =E23+E24+E25 -> 1962608.8 | F26: =F23+F24+F25 -> 2524761 | G26: =G23+G24+G25 -> 2524761 | H26: =H23+H24+H25 -> 2524761
B27: Cumulative | C27: =C26 -> -590000 | D27: =C27+D26 -> -32771.701 | E27: =D27+E26 -> 1929837.1 | F27: =E27+F26 -> 4454598.1 | G27: =F27+G26 -> 6979359.1 | H27: =G27+H26 -> 9504120.1
B29: NPV (5 yr) | C29: =C26+NPV(Assumptions!C89,D26:H26) -> 7186894.1
B30: IRR | C30: =IFERROR(IRR(C26:H26),"n/a") -> 1.868587
B31: Payback crossing (helper) | D31: =IF(AND(C27<0,D27>=0),12*0+12*(-C27/D26),9999) -> 9999 | E31: =IF(AND(D27<0,E27>=0),12*1+12*(-D27/E26),9999) -> 12.200376 | F31: =IF(AND(E27<0,F27>=0),12*2+12*(-E27/F26),9999) -> 9999 | G31: =IF(AND(F27<0,G27>=0),12*3+12*(-F27/G26),9999) -> 9999 | H31: =IF(AND(G27<0,H27>=0),12*4+12*(-G27/H26),9999) -> 9999
B32: Payback (months) | C32: =IF(MIN(D31:H31)>=9999,"beyond 5 yrs",MIN(D31:H31)) -> 12.200376
B33: 5-year cumulative return on capital | C33: =IFERROR(H27/Investment!D10,0) -> 16.108678
B36: Phase 0+1 is the number to lead with: no regulatory approval, no consent framework, no device pathway.

Sheet Sensitivity
B1: Sensitivity
B2: The four inputs that move the answer most. Change the driver on Assumptions and watch these.
B4: Current model output
B5: Total annual value, undiscounted | C5: =Outcomes!C38 -> 6824616.1
B6: Total annual value, after soft-dollar discount | C6: =Outcomes!C44 -> 6824616.1
B7: Phase 0+1 annual value, discounted | C7: =Outcomes!C45 -> 2810761
B8: Total FTE-equivalents | C8: =Outcomes!D38 -> 52.174679
B9: of which actual headcount | C9: =Outcomes!D40 -> 28.586538
B10: Full deployment capital | C10: =Investment!C10 -> 2645000
B11: Phase 0+1 capital | C11: =Investment!D10 -> 590000
B13: What breaks this, in order of impact
B14: Soft-dollar discount | C14: Finance will haircut augment outcomes 30-50%. At 40%, total falls by roughly a quarter and payback stretches by six months. Model it yourself before they do.
B15: Occupancy | C15: Outcome 2 is worth nothing if the hospital is not capacity-constrained, and 3-5x the estimate if it is. Ask about occupancy and boarding hours before quoting.
B16: Payer mix | C16: Contribution margin per admission ranges under $1,000 to over $5,000. That single input swings outcomes 2 and 4 threefold.
B17: Outcome 6 gating | C17: Remove sitter substitution and actual headcount reduction goes to zero. The case becomes entirely soft dollars, which is a different conversation.
B18: Adoption | C18: Every hour assumes clinicians use it. A voice interface people route around returns nothing. No spreadsheet captures this.
B19: Workforce reception | C19: Sitter reduction affects real people and turns a technology programme into a labour negotiation. Frame as redeployment to short-staffed direct care roles, and raise it before deployment.
B21: The honest one-line version
B22: For a 400-bed hospital: roughly $4M to $6M of annual value and about 55 FTE-equivalents of capacity, of which realistically 30 or so is genuine headcount and all of it sits in the hardest use case. The operations-only entry point delivers roughly $2.3M for under $600K of capital and pays back inside a year. The strategic argument is not headcount. It is handing capacity back to a workforce that is already short, in a market where you cannot hire your way out.
